[2023-05-29 02:09:14,555] {taskinstance.py:1159} INFO - Dependencies all met for <TaskInstance: ML_data_pipeline_demo.model_training manual__2023-05-29T02:09:11.743924+00:00 [queued]>
[2023-05-29 02:09:14,587] {taskinstance.py:1159} INFO - Dependencies all met for <TaskInstance: ML_data_pipeline_demo.model_training manual__2023-05-29T02:09:11.743924+00:00 [queued]>
[2023-05-29 02:09:14,588] {taskinstance.py:1356} INFO - 
--------------------------------------------------------------------------------
[2023-05-29 02:09:14,590] {taskinstance.py:1357} INFO - Starting attempt 1 of 1
[2023-05-29 02:09:14,591] {taskinstance.py:1358} INFO - 
--------------------------------------------------------------------------------
[2023-05-29 02:09:14,638] {taskinstance.py:1377} INFO - Executing <Task(PythonOperator): model_training> on 2023-05-29 02:09:11.743924+00:00
[2023-05-29 02:09:14,670] {standard_task_runner.py:52} INFO - Started process 22620 to run task
[2023-05-29 02:09:14,685] {standard_task_runner.py:79} INFO - Running: ['***', 'tasks', 'run', 'ML_data_pipeline_demo', 'model_training', 'manual__2023-05-29T02:09:11.743924+00:00', '--job-id', '14', '--raw', '--subdir', 'DAGS_FOLDER/my_dag.py', '--cfg-path', '/tmp/tmp0_6jke0g', '--error-file', '/tmp/tmpydung4ll']
[2023-05-29 02:09:14,687] {standard_task_runner.py:80} INFO - Job 14: Subtask model_training
[2023-05-29 02:09:14,823] {task_command.py:369} INFO - Running <TaskInstance: ML_data_pipeline_demo.model_training manual__2023-05-29T02:09:11.743924+00:00 [running]> on host e6406d4dfe47
[2023-05-29 02:09:14,949] {taskinstance.py:1571} INFO - Exporting the following env vars:
AIRFLOW_CTX_DAG_OWNER=***
AIRFLOW_CTX_DAG_ID=ML_data_pipeline_demo
AIRFLOW_CTX_TASK_ID=model_training
AIRFLOW_CTX_EXECUTION_DATE=2023-05-29T02:09:11.743924+00:00
AIRFLOW_CTX_TRY_NUMBER=1
AIRFLOW_CTX_DAG_RUN_ID=manual__2023-05-29T02:09:11.743924+00:00
[2023-05-29 02:09:30,845] {taskinstance.py:1889} ERROR - Task failed with exception
Traceback (most recent call last):
  File "/home/airflow/.local/lib/python3.7/site-packages/airflow/operators/python.py", line 171, in execute
    return_value = self.execute_callable()
  File "/home/airflow/.local/lib/python3.7/site-packages/airflow/operators/python.py", line 189, in execute_callable
    return self.python_callable(*self.op_args, **self.op_kwargs)
  File "/opt/airflow/dags/my_dag.py", line 44, in run_ML_model_training_polyreg
    ML_model_training_polyreg.ML_model_training()
  File "/opt/airflow/dags/tasks/ML_model_training_polyreg.py", line 57, in ML_model_training
    poly_reg_rmse = ML_model_training_polyreg(data_avg, feature, target, model_filename)
  File "/opt/airflow/dags/tasks/ML_model_training_polyreg.py", line 42, in ML_model_training_polyreg
    pickle.dump(poly_reg_model, open(model_filename, 'wb'))
FileNotFoundError: [Errno 2] No such file or directory: '/opt/airflow/data/trained_model/ml_model.pkl'
[2023-05-29 02:09:30,903] {taskinstance.py:1400} INFO - Marking task as FAILED. dag_id=ML_data_pipeline_demo, task_id=model_training, execution_date=20230529T020911, start_date=20230529T020914, end_date=20230529T020930
[2023-05-29 02:09:30,960] {standard_task_runner.py:97} ERROR - Failed to execute job 14 for task model_training ([Errno 2] No such file or directory: '/opt/airflow/data/trained_model/ml_model.pkl'; 22620)
[2023-05-29 02:09:33,420] {local_task_job.py:156} INFO - Task exited with return code 1
[2023-05-29 02:09:33,614] {local_task_job.py:273} INFO - 0 downstream tasks scheduled from follow-on schedule check
