[2023-05-29 00:28:24,924] {taskinstance.py:1159} INFO - Dependencies all met for <TaskInstance: ML_data_pipeline_demo.process_raw_data manual__2023-05-29T00:22:49.432050+00:00 [queued]>
[2023-05-29 00:28:24,947] {taskinstance.py:1159} INFO - Dependencies all met for <TaskInstance: ML_data_pipeline_demo.process_raw_data manual__2023-05-29T00:22:49.432050+00:00 [queued]>
[2023-05-29 00:28:24,948] {taskinstance.py:1356} INFO - 
--------------------------------------------------------------------------------
[2023-05-29 00:28:24,950] {taskinstance.py:1357} INFO - Starting attempt 1 of 1
[2023-05-29 00:28:24,951] {taskinstance.py:1358} INFO - 
--------------------------------------------------------------------------------
[2023-05-29 00:28:24,977] {taskinstance.py:1377} INFO - Executing <Task(PythonOperator): process_raw_data> on 2023-05-29 00:22:49.432050+00:00
[2023-05-29 00:28:24,992] {standard_task_runner.py:52} INFO - Started process 740 to run task
[2023-05-29 00:28:24,998] {standard_task_runner.py:79} INFO - Running: ['***', 'tasks', 'run', 'ML_data_pipeline_demo', 'process_raw_data', 'manual__2023-05-29T00:22:49.432050+00:00', '--job-id', '3', '--raw', '--subdir', 'DAGS_FOLDER/my_dag.py', '--cfg-path', '/tmp/tmpt5ieqsww', '--error-file', '/tmp/tmpop2c9qd4']
[2023-05-29 00:28:25,000] {standard_task_runner.py:80} INFO - Job 3: Subtask process_raw_data
[2023-05-29 00:28:25,114] {task_command.py:369} INFO - Running <TaskInstance: ML_data_pipeline_demo.process_raw_data manual__2023-05-29T00:22:49.432050+00:00 [running]> on host e6406d4dfe47
[2023-05-29 00:28:25,257] {taskinstance.py:1571} INFO - Exporting the following env vars:
AIRFLOW_CTX_DAG_OWNER=***
AIRFLOW_CTX_DAG_ID=ML_data_pipeline_demo
AIRFLOW_CTX_TASK_ID=process_raw_data
AIRFLOW_CTX_EXECUTION_DATE=2023-05-29T00:22:49.432050+00:00
AIRFLOW_CTX_TRY_NUMBER=1
AIRFLOW_CTX_DAG_RUN_ID=manual__2023-05-29T00:22:49.432050+00:00
[2023-05-29 00:42:57,532] {taskinstance.py:1889} ERROR - Task failed with exception
Traceback (most recent call last):
  File "/home/airflow/.local/lib/python3.7/site-packages/airflow/operators/python.py", line 171, in execute
    return_value = self.execute_callable()
  File "/home/airflow/.local/lib/python3.7/site-packages/airflow/operators/python.py", line 189, in execute_callable
    return self.python_callable(*self.op_args, **self.op_kwargs)
  File "/opt/airflow/dags/my_dag.py", line 38, in run_process_raw_data
    process_raw_data.process_raw_data()
  File "/opt/airflow/dags/tasks/process_raw_data.py", line 103, in process_raw_data
    os.rmdir(f'{raw_data_path}/etfs')
OSError: [Errno 39] Directory not empty: '/opt/airflow/data/raw_data/etfs'
[2023-05-29 00:42:57,588] {taskinstance.py:1400} INFO - Marking task as FAILED. dag_id=ML_data_pipeline_demo, task_id=process_raw_data, execution_date=20230529T002249, start_date=20230529T002824, end_date=20230529T004257
[2023-05-29 00:42:57,625] {standard_task_runner.py:97} ERROR - Failed to execute job 3 for task process_raw_data ([Errno 39] Directory not empty: '/opt/airflow/data/raw_data/etfs'; 740)
[2023-05-29 00:42:57,768] {local_task_job.py:156} INFO - Task exited with return code 1
[2023-05-29 00:42:57,840] {local_task_job.py:273} INFO - 0 downstream tasks scheduled from follow-on schedule check
