[2023-05-29 02:04:52,894] {taskinstance.py:1159} INFO - Dependencies all met for <TaskInstance: ML_data_pipeline_demo.model_training manual__2023-05-29T02:04:50.344447+00:00 [queued]>
[2023-05-29 02:04:52,913] {taskinstance.py:1159} INFO - Dependencies all met for <TaskInstance: ML_data_pipeline_demo.model_training manual__2023-05-29T02:04:50.344447+00:00 [queued]>
[2023-05-29 02:04:52,915] {taskinstance.py:1356} INFO - 
--------------------------------------------------------------------------------
[2023-05-29 02:04:52,917] {taskinstance.py:1357} INFO - Starting attempt 1 of 1
[2023-05-29 02:04:52,918] {taskinstance.py:1358} INFO - 
--------------------------------------------------------------------------------
[2023-05-29 02:04:52,947] {taskinstance.py:1377} INFO - Executing <Task(PythonOperator): model_training> on 2023-05-29 02:04:50.344447+00:00
[2023-05-29 02:04:52,964] {standard_task_runner.py:52} INFO - Started process 22454 to run task
[2023-05-29 02:04:52,982] {standard_task_runner.py:79} INFO - Running: ['***', 'tasks', 'run', 'ML_data_pipeline_demo', 'model_training', 'manual__2023-05-29T02:04:50.344447+00:00', '--job-id', '12', '--raw', '--subdir', 'DAGS_FOLDER/my_dag.py', '--cfg-path', '/tmp/tmpv2xtxqem', '--error-file', '/tmp/tmpe7qd_cpn']
[2023-05-29 02:04:52,985] {standard_task_runner.py:80} INFO - Job 12: Subtask model_training
[2023-05-29 02:04:53,201] {task_command.py:369} INFO - Running <TaskInstance: ML_data_pipeline_demo.model_training manual__2023-05-29T02:04:50.344447+00:00 [running]> on host e6406d4dfe47
[2023-05-29 02:04:53,429] {taskinstance.py:1571} INFO - Exporting the following env vars:
AIRFLOW_CTX_DAG_OWNER=***
AIRFLOW_CTX_DAG_ID=ML_data_pipeline_demo
AIRFLOW_CTX_TASK_ID=model_training
AIRFLOW_CTX_EXECUTION_DATE=2023-05-29T02:04:50.344447+00:00
AIRFLOW_CTX_TRY_NUMBER=1
AIRFLOW_CTX_DAG_RUN_ID=manual__2023-05-29T02:04:50.344447+00:00
[2023-05-29 02:05:27,732] {taskinstance.py:1889} ERROR - Task failed with exception
Traceback (most recent call last):
  File "/home/airflow/.local/lib/python3.7/site-packages/airflow/operators/python.py", line 171, in execute
    return_value = self.execute_callable()
  File "/home/airflow/.local/lib/python3.7/site-packages/airflow/operators/python.py", line 189, in execute_callable
    return self.python_callable(*self.op_args, **self.op_kwargs)
  File "/opt/airflow/dags/my_dag.py", line 44, in run_ML_model_training_polyreg
    ML_model_training_polyreg.ML_model_training()
  File "/opt/airflow/dags/tasks/ML_model_training_polyreg.py", line 58, in ML_model_training
    ts = str(datetime.now())
NameError: name 'datetime' is not defined
[2023-05-29 02:05:27,871] {taskinstance.py:1400} INFO - Marking task as FAILED. dag_id=ML_data_pipeline_demo, task_id=model_training, execution_date=20230529T020450, start_date=20230529T020452, end_date=20230529T020527
[2023-05-29 02:05:27,990] {standard_task_runner.py:97} ERROR - Failed to execute job 12 for task model_training (name 'datetime' is not defined; 22454)
[2023-05-29 02:05:30,418] {local_task_job.py:221} WARNING - State of this instance has been externally set to failed. Terminating instance.
[2023-05-29 02:05:30,559] {process_utils.py:129} INFO - Sending Signals.SIGTERM to group 22454. PIDs of all processes in the group: [22454]
[2023-05-29 02:05:30,617] {process_utils.py:80} INFO - Sending the signal Signals.SIGTERM to group 22454
[2023-05-29 02:05:30,798] {process_utils.py:75} INFO - Process psutil.Process(pid=22454, status='terminated', exitcode=1, started='02:04:52') (22454) terminated with exit code 1
